#VRML_SIM R2023b utf8

EXTERNPROTO "https://raw.githubusercontent.com/cyberbotics/webots/R2023b/projects/objects/backgrounds/protos/TexturedBackground.proto"
EXTERNPROTO "https://raw.githubusercontent.com/cyberbotics/webots/R2023b/projects/objects/backgrounds/protos/TexturedBackgroundLight.proto"
EXTERNPROTO "https://raw.githubusercontent.com/cyberbotics/webots/R2023b/projects/objects/floors/protos/RectangleArena.proto"

WorldInfo {
}
Viewpoint {
  orientation 0.10982422294804771 0.13231010866945614 -0.985105413241514 1.4003409430696563
  position -0.48883623600345105 2.1069350452758218 0.4998861019688809
}
TexturedBackground {
}
TexturedBackgroundLight {
}
RectangleArena {
  translation 0 0 -0.11
  floorSize 6 2
}
Robot {
  translation 0.00051761 1.933882430999158e-18 0.14995456000000001
  rotation -0.9998797680119812 0.012769551973586315 0.008797048522122534 1.1215030522639737e-17
  children [
    HingeJoint {
      jointParameters HingeJointParameters {
        axis 0 1 0
        anchor 0 -0.13 -0.0401
      }
      device [
        RotationalMotor {
          name "bm2"
        }
      ]
      endPoint Solid {
        translation 0 -0.13 -0.0401
        rotation 1 0 0 1.57
        children [
          Solid {
            translation 0 -0.09992 0.10008
            rotation 1 0 0 1.57
            children [
              Solid {
                translation 0 0 0.11
                children [
                  DEF big_foot Shape {
                    appearance PBRAppearance {
                      baseColor 0 0 0
                      metalness 0
                    }
                    geometry Box {
                      size 0.5 0.1 0.01
                    }
                  }
                ]
                boundingObject USE big_foot
                physics Physics {
                }
              }
              DEF rod Shape {
                appearance PBRAppearance {
                  baseColor 0 0 0
                  roughness 1
                  metalness 0
                }
                geometry Cylinder {
                  height 0.2
                  radius 0.004
                }
              }
            ]
            boundingObject USE rod
            physics Physics {
            }
          }
          DEF mover Shape {
            appearance PBRAppearance {
              baseColor 0 0 0
              metalness 0
            }
            geometry Cylinder {
              height 0.2
              radius 0.004
            }
          }
        ]
        name "solid(3)"
        boundingObject USE mover
        physics Physics {
        }
      }
    }
    HingeJoint {
      jointParameters HingeJointParameters {
        axis 0 1 0
        anchor 0 0.13 -0.0401
      }
      device [
        RotationalMotor {
          name "bm1"
        }
      ]
      endPoint Solid {
        translation -9.93253483271379e-06 0.12996800000000125 -0.04011612587019785
        rotation 1 -1.9031431690294748e-10 -1.904680116578122e-10 1.5700000003195536
        children [
          Solid {
            translation 0 -0.099848 -0.0998801
            rotation 1 0 0 1.57
            children [
              Solid {
                translation 0 0 0.1
                children [
                  DEF big_foot Shape {
                    appearance PBRAppearance {
                      baseColor 0 0 0
                      metalness 0
                    }
                    geometry Box {
                      size 0.5 0.1 0.01
                    }
                  }
                ]
                boundingObject USE big_foot
                physics Physics {
                }
              }
              DEF rod Shape {
                appearance PBRAppearance {
                  baseColor 0 0 0
                  roughness 1
                  metalness 0
                }
                geometry Cylinder {
                  height 0.2
                  radius 0.004
                }
              }
            ]
            boundingObject USE rod
            physics Physics {
            }
          }
          DEF mover Shape {
            appearance PBRAppearance {
              baseColor 0 0 0
              metalness 0
            }
            geometry Cylinder {
              height 0.2
              radius 0.004
            }
          }
        ]
        name "solid(2)"
        boundingObject USE mover
        physics Physics {
        }
      }
    }
    DEF body Pose {
      translation 3.17068e-09 0 -0.06
      rotation 0 1 0 1.57
      children [
        Shape {
          appearance PBRAppearance {
            baseColor 0.7 0 1
            roughness 1
            metalness 0
          }
          geometry Box {
            size 0.07 0.1 0.16
          }
        }
      ]
    }
    DEF leg2 HingeJoint {
      jointParameters HingeJointParameters {
        axis 0 1 0
        anchor 0 -0.05 -0.07
      }
      device [
        PositionSensor {
          name "ps_tl2"
        }
        RotationalMotor {
          name "tl2"
        }
      ]
      endPoint DEF mover Solid {
        translation -0.0012513697268864668 -0.05419954978691925 -0.07239814875166875
        rotation 0.9999981829446173 -0.0015702148832268047 -0.0010809869028947 1.593306526845865
        children [
          DEF tl Solid {
            translation -9.978538010683601e-06 -0.04119659644083781 0.0171097127225619
            rotation 0.9965166472351025 -3.320506684108147e-05 0.08339406861842186 0.0007989497796542277
            children [
              HingeJoint {
                jointParameters HingeJointParameters {
                  position 5.101435191625911e-07
                  axis 0 0 1
                  anchor -0.014 -0.049 0
                }
                device [
                  PositionSensor {
                    name "ps_bl2"
                  }
                  RotationalMotor {
                    name "bl2"
                  }
                ]
                endPoint DEF mover Solid {
                  translation -0.01399999913028595 -0.04899012289244684 -2.9067304119223544e-12
                  rotation 0 0 1 5.101335873789709e-07
                  children [
                    DEF bl2 Solid {
                      translation 0.014 -0.05 0
                      children [
                        DEF foot Solid {
                          translation 2.1265601074175274e-07 -0.04683254818540883 2.389488095902448e-06
                          rotation 0.002383716656664445 6.940810074644534e-09 -0.9999971589434143 6.713801053105515e-05
                          children [
                            DEF foot Shape {
                              appearance PBRAppearance {
                                baseColor 1 0 0
                                roughness 1
                                metalness 0
                              }
                              geometry Box {
                                size 0.04 0.006 0.04
                              }
                            }
                          ]
                          boundingObject USE foot
                          physics Physics {
                          }
                        }
                        DEF bl Shape {
                          appearance PBRAppearance {
                            baseColor 1 0 0
                            roughness 1
                            metalness 0
                          }
                          geometry Box {
                            size 0.03 0.1 0.03
                          }
                        }
                      ]
                      boundingObject USE bl
                      physics Physics {
                      }
                    }
                    DEF mover Shape {
                      appearance PBRAppearance {
                        baseColor 0 0 0
                        roughness 1
                        metalness 0
                      }
                      geometry Cylinder {
                        height 0.025
                        radius 0.004
                      }
                    }
                  ]
                  boundingObject USE mover
                  physics Physics {
                  }
                }
              }
              DEF tl Shape {
                appearance PBRAppearance {
                  baseColor 1 0 0
                  roughness 1
                  metalness 0
                }
                geometry Box {
                  size 0.03 0.1 0.03
                }
              }
            ]
            boundingObject USE tl
            physics Physics {
            }
          }
          DEF mover Shape {
            appearance PBRAppearance {
              baseColor 0 0 0
              metalness 0
            }
            geometry Cylinder {
              height 0.025
              radius 0.004
            }
          }
        ]
        name "solid(1)"
        boundingObject USE mover
        physics Physics {
        }
      }
    }
    DEF leg1 HingeJoint {
      jointParameters HingeJointParameters {
        position 1.1429110151229993e-23
        axis 0 1 0
        anchor 0 0.05 -0.07
      }
      device [
        PositionSensor {
          name "ps_tl1"
        }
        RotationalMotor {
          name "tl1"
        }
      ]
      endPoint DEF mover Solid {
        translation 0.000614247640603423 0.052782050603812365 -0.07212802842543722
        rotation 0.9999935222871132 0.0028900796076743443 0.0021454192304082003 1.5406914477983846
        children [
          DEF tl1 Solid {
            translation -8.105930313217827e-06 -0.038212762560222324 -0.016885540345895636
            rotation 0.9977969772092015 -6.3654940682848635e-06 0.06634148198270061 0.0007977446183631103
            children [
              HingeJoint {
                jointParameters HingeJointParameters {
                  position 9.014598836016546e-08
                  axis 0 0 1
                  anchor -0.014 -0.049 0
                }
                device [
                  PositionSensor {
                    name "ps_bl1"
                  }
                  RotationalMotor {
                    name "bl1"
                  }
                ]
                endPoint DEF mover Solid {
                  translation -0.014071805102779698 -0.050121197128189875 0.0007523451276918451
                  rotation 0.9810856465911432 0.18525987547164124 0.0561224785007819 8.024520884654731e-07
                  children [
                    DEF bl1 Solid {
                      translation 0.014 -0.05 0
                      children [
                        DEF foot Solid {
                          translation 0 -0.05 0
                          children [
                            DEF foot Shape {
                              appearance PBRAppearance {
                                baseColor 1 0 0
                                roughness 1
                                metalness 0
                              }
                              geometry Box {
                                size 0.04 0.006 0.04
                              }
                            }
                          ]
                          boundingObject USE foot
                          physics Physics {
                          }
                        }
                        DEF bl Shape {
                          appearance PBRAppearance {
                            baseColor 1 0 0
                            roughness 1
                            metalness 0
                          }
                          geometry Box {
                            size 0.03 0.1 0.03
                          }
                        }
                      ]
                      boundingObject USE bl
                      physics Physics {
                      }
                    }
                    DEF mover Shape {
                      appearance PBRAppearance {
                        baseColor 0 0 0
                        roughness 1
                        metalness 0
                      }
                      geometry Cylinder {
                        height 0.025
                        radius 0.004
                      }
                    }
                  ]
                  boundingObject USE mover
                  physics Physics {
                  }
                }
              }
              DEF tl Shape {
                appearance PBRAppearance {
                  baseColor 1 0 0
                  roughness 1
                  metalness 0
                }
                geometry Box {
                  size 0.03 0.1 0.03
                }
              }
            ]
            boundingObject USE tl
            physics Physics {
            }
          }
          DEF mover Shape {
            appearance PBRAppearance {
              baseColor 0 0 0
              metalness 0
            }
            geometry Cylinder {
              height 0.025
              radius 0.004
            }
          }
        ]
        boundingObject USE mover
        physics Physics {
        }
      }
    }
  ]
  boundingObject USE body
  physics Physics {
  }
  controller "walk_bot"
}
